<?xml version="1.0" encoding="utf-8"?>
<!-- This URDF was automatically created by SolidWorks to URDF Exporter! Originally created by Stephen Brawner (brawner@gmail.com) 
     Commit Version: 1.6.0-1-g15f4949  Build Version: 1.6.7594.29634
     For more information, please see http://wiki.ros.org/sw_urdf_exporter -->
<robot
  name="SURover22_description_byerenna" >
  <link
    name="base_link">
    <inertial>
      <origin
        xyz="0.00023486 -4.4786E-05 -0.14162"
        rpy="0 0 0" />
      <mass
        value="20.605" />
      <inertia
        ixx="0.454"
        ixy="1.9549E-09"
        ixz="0.00084823"
        iyy="1.0629"
        iyz="1.6096E-08"
        izz="1.4823" />
    </inertial>
    <visual>
      <origin
        xyz="0 0 0"
        rpy="0 0 0" />
      <geometry>
        <mesh
          filename="package://SURover22_description_byerenna/meshes/base_link.STL" />
      </geometry>
      <material
        name="">
        <color
          rgba="0.7451 0.7451 0.7451 1" />
      </material>
    </visual>
    <collision>
      <origin
        xyz="0 0 0"
        rpy="0 0 0" />
      <geometry>
        <mesh
          filename="package://SURover22_description_byerenna/meshes/base_link.STL" />
      </geometry>
    </collision>
  </link>
  <link
    name="R-front">
    <inertial>
      <origin
        xyz="8.8818E-16 -0.0375 1.6653E-16"
        rpy="0 0 0" />
      <mass
        value="2.3326" />
      <inertia
        ixx="0.0069833"
        ixy="-1.1181E-16"
        ixz="7.4623E-19"
        iyy="0.01178"
        iyz="-2.014E-17"
        izz="0.0069833" />
    </inertial>
    <visual>
      <origin
        xyz="0 0 0"
        rpy="0 0 0" />
      <geometry>
        <mesh
          filename="package://SURover22_description_byerenna/meshes/R-front.STL" />
      </geometry>
      <material
        name="">
        <color
          rgba="0.79216 0.81961 0.93333 1" />
      </material>
    </visual>
    <collision>
      <origin
        xyz="0 0 0"
        rpy="0 0 0" />
      <geometry>
        <mesh
          filename="package://SURover22_description_byerenna/meshes/R-front.STL" />
      </geometry>
    </collision>
  </link>
  <joint
    name="joint_R_f"
    type="continuous">
    <origin
      xyz="0.548838296645782 -0.351080000000064 -0.428087514508932"
      rpy="0 0 0" />
    <parent
      link="base_link" />
    <child
      link="R-front" />
    <axis
      xyz="0 1 0" />
  </joint>
  <link
    name="R-mid">
    <inertial>
      <origin
        xyz="-5.55111512312578E-17 -0.0375000000000623 -5.55111512312578E-17"
        rpy="0 0 0" />
      <mass
        value="2.33263254529042" />
      <inertia
        ixx="0.0069833186824632"
        ixy="-1.30245751233354E-19"
        ixz="-7.41033887658693E-19"
        iyy="0.0117797943537166"
        iyz="1.28115366404075E-19"
        izz="0.0069833186824632" />
    </inertial>
    <visual>
      <origin
        xyz="0 0 0"
        rpy="0 0 0" />
      <geometry>
        <mesh
          filename="package://SURover22_description_byerenna/meshes/R-mid.STL" />
      </geometry>
      <material
        name="">
        <color
          rgba="0.792156862745098 0.819607843137255 0.933333333333333 1" />
      </material>
    </visual>
    <collision>
      <origin
        xyz="0 0 0"
        rpy="0 0 0" />
      <geometry>
        <mesh
          filename="package://SURover22_description_byerenna/meshes/R-mid.STL" />
      </geometry>
    </collision>
  </link>
  <joint
    name="joint_R_m"
    type="continuous">
    <origin
      xyz="0.068456 -0.38608 -0.42809"
      rpy="0 0 0" />
    <parent
      link="base_link" />
    <child
      link="R-mid" />
    <axis
      xyz="0 1 0" />
  </joint>
  <link
    name="R-rear">
    <inertial>
      <origin
        xyz="6.3838E-15 -0.0375 -5.107E-15"
        rpy="0 0 0" />
      <mass
        value="2.3326" />
      <inertia
        ixx="0.0069833"
        ixy="-8.3231E-16"
        ixz="8.0388E-19"
        iyy="0.01178"
        iyz="6.734E-16"
        izz="0.0069833" />
    </inertial>
    <visual>
      <origin
        xyz="0 0 0"
        rpy="0 0 0" />
      <geometry>
        <mesh
          filename="package://SURover22_description_byerenna/meshes/R-rear.STL" />
      </geometry>
      <material
        name="">
        <color
          rgba="0.79216 0.81961 0.93333 1" />
      </material>
    </visual>
    <collision>
      <origin
        xyz="0 0 0"
        rpy="0 0 0" />
      <geometry>
        <mesh
          filename="package://SURover22_description_byerenna/meshes/R-rear.STL" />
      </geometry>
    </collision>
  </link>
  <joint
    name="joint_R_r"
    type="continuous">
    <origin
      xyz="-0.43561 -0.38608 -0.42822"
      rpy="0 0 0" />
    <parent
      link="base_link" />
    <child
      link="R-rear" />
    <axis
      xyz="0 1 0" />
  </joint>
  <link
    name="L-front">
    <inertial>
      <origin
        xyz="9.992E-16 -0.0375 0"
        rpy="0 0 0" />
      <mass
        value="2.3326" />
      <inertia
        ixx="0.0069833"
        ixy="-1.245E-16"
        ixz="-6.9538E-33"
        iyy="0.01178"
        iyz="2.6789E-19"
        izz="0.0069833" />
    </inertial>
    <visual>
      <origin
        xyz="0 0 0"
        rpy="0 0 0" />
      <geometry>
        <mesh
          filename="package://SURover22_description_byerenna/meshes/L-front.STL" />
      </geometry>
      <material
        name="">
        <color
          rgba="0.79216 0.81961 0.93333 1" />
      </material>
    </visual>
    <collision>
      <origin
        xyz="0 0 0"
        rpy="0 0 0" />
      <geometry>
        <mesh
          filename="package://SURover22_description_byerenna/meshes/L-front.STL" />
      </geometry>
    </collision>
  </link>
  <joint
    name="joint_L_f"
    type="continuous">
    <origin
      xyz="0.548812606572592 0.426079999999846 -0.428126101607028"
      rpy="0 0 0" />
    <parent
      link="base_link" />
    <child
      link="L-front" />
    <axis
      xyz="0 1 0" />
  </joint>
  <link
    name="L-mid">
    <inertial>
      <origin
        xyz="4.774E-15 -0.0375 -3.3307E-16"
        rpy="0 0 0" />
      <mass
        value="2.3326" />
      <inertia
        ixx="0.0069833"
        ixy="-6.1418E-16"
        ixz="-2.7012E-19"
        iyy="0.01178"
        iyz="5.0407E-17"
        izz="0.0069833" />
    </inertial>
    <visual>
      <origin
        xyz="0 0 0"
        rpy="0 0 0" />
      <geometry>
        <mesh
          filename="package://SURover22_description_byerenna/meshes/L-mid.STL" />
      </geometry>
      <material
        name="">
        <color
          rgba="0.79216 0.81961 0.93333 1" />
      </material>
    </visual>
    <collision>
      <origin
        xyz="0 0 0"
        rpy="0 0 0" />
      <geometry>
        <mesh
          filename="package://SURover22_description_byerenna/meshes/L-mid.STL" />
      </geometry>
    </collision>
  </link>
  <joint
    name="joint_L_m"
    type="continuous">
    <origin
      xyz="0.068429 0.46108 -0.42809"
      rpy="0 0 0" />
    <parent
      link="base_link" />
    <child
      link="L-mid" />
    <axis
      xyz="0 1 0" />
  </joint>
  <link
    name="L-rear">
    <inertial>
      <origin
        xyz="4.774E-15 -0.0375 -5.9952E-15"
        rpy="0 0 0" />
      <mass
        value="2.3326" />
      <inertia
        ixx="0.0069833"
        ixy="-6.2773E-16"
        ixz="-2.1099E-19"
        iyy="0.01178"
        iyz="7.7451E-16"
        izz="0.0069833" />
    </inertial>
    <visual>
      <origin
        xyz="0 0 0"
        rpy="0 0 0" />
      <geometry>
        <mesh
          filename="package://SURover22_description_byerenna/meshes/L-rear.STL" />
      </geometry>
      <material
        name="">
        <color
          rgba="0.79216 0.81961 0.93333 1" />
      </material>
    </visual>
    <collision>
      <origin
        xyz="0 0 0"
        rpy="0 0 0" />
      <geometry>
        <mesh
          filename="package://SURover22_description_byerenna/meshes/L-rear.STL" />
      </geometry>
    </collision>
  </link>
  <joint
    name="joint_L_r"
    type="continuous">
    <origin
      xyz="-0.43564 0.46108 -0.42817"
      rpy="0 0 0" />
    <parent
      link="base_link" />
    <child
      link="L-rear" />
    <axis
      xyz="0 1 0" />
  </joint>



<transmission name="left_front_trans" type="SimpleTransmission">
    <type>transmission_interface/SimpleTransmission</type>
    <actuator name="left_front_motor">
      <mechanicalReduction>1</mechanicalReduction>
    </actuator>
    <joint name="joint_L_f">
      <hardwareInterface>hardware_interface/VelocityJointInterface</hardwareInterface>
    </joint>
  </transmission>

  <transmission name="right_front_trans" type="SimpleTransmission">
    <type>transmission_interface/SimpleTransmission</type>
    <actuator name="right_front_motor">
      <mechanicalReduction>1</mechanicalReduction>
    </actuator>
    <joint name="joint_R_f">
      <hardwareInterface>hardware_interface/VelocityJointInterface</hardwareInterface>
    </joint>
  </transmission>

  <transmission name="left_mid_trans" type="SimpleTransmission">
    <type>transmission_interface/SimpleTransmission</type>
    <actuator name="left_mid_motor">
      <mechanicalReduction>1</mechanicalReduction>
    </actuator>
    <joint name="joint_L_m">
      <hardwareInterface>hardware_interface/VelocityJointInterface</hardwareInterface>
    </joint>
  </transmission>

  <transmission name="right_mid_trans" type="SimpleTransmission">
    <type>transmission_interface/SimpleTransmission</type>
    <actuator name="right_mid_motor">
      <mechanicalReduction>1</mechanicalReduction>
    </actuator>
    <joint name="joint_R_m">
      <hardwareInterface>hardware_interface/VelocityJointInterface</hardwareInterface>
    </joint>
  </transmission>

  <transmission name="left_rear_trans" type="SimpleTransmission">
    <type>transmission_interface/SimpleTransmission</type>
    <actuator name="left_rear_motor">
      <mechanicalReduction>1</mechanicalReduction>
    </actuator>
    <joint name="joint_L_r">
      <hardwareInterface>hardware_interface/VelocityJointInterface</hardwareInterface>
    </joint>
  </transmission>

  <transmission name="right_rear_trans" type="SimpleTransmission">
    <type>transmission_interface/SimpleTransmission</type>
    <actuator name="right_rear_motor">
      <mechanicalReduction>1</mechanicalReduction>
    </actuator>
    <joint name="joint_R_r">
      <hardwareInterface>hardware_interface/VelocityJointInterface</hardwareInterface>
    </joint>
  </transmission>



<!--
  <gazebo>
    <plugin name="diffdrive_plugin_6w" filename="libdiffdrive_plugin_6w.so">
      <alwaysOn>true</alwaysOn>
      <updateRate>30.0</updateRate>

      <frontLeftJoint>joint_L_f</frontLeftJoint>
      <frontRightJoint>joint_R_f</frontRightJoint>
      <midLeftJoint>joint_L_m</midLeftJoint>
      <midRightJoint>joint_R_m</midRightJoint>
      <rearLeftJoint>joint_L_r</rearLeftJoint>
      <rearRightJoint>joint_R_r</rearRightJoint>
      
      <wheelSeparation>0.44</wheelSeparation>
      <wheelDiameter>0.3</wheelDiameter>
      <torque>100</torque>
      
      <robotBaseFrame>base_footprint</robotBaseFrame>
      <commandTopic>cmd_vel</commandTopic>
      <odometryTopic>odom</odometryTopic>
      <odometryFrame>odom</odometryFrame>
      <broadcastTF>true</broadcastTF>
    </plugin>


</gazebo>
  -->


  <gazebo>
    <plugin name="gazebo_ros_control" filename="libgazebo_ros_control.so">
      <!-- <robotSimType>gazebo_ros_control/DefaultRobotHWSim</robotSimType> -->
      
    </plugin>
  </gazebo>



<!--

  <gazebo reference="imu_link">
    <sensor type="imu" name="imu">
      <always_on>true</always_on>
      <visualize>true</visualize>
    </sensor>
    <material>Gazebo/Grey</material>
  </gazebo>

  <gazebo>
    <plugin name="imu_plugin" filename="libgazebo_ros_imu.so">
      <alwaysOn>true</alwaysOn>
      <bodyName>base_link</bodyName>
      <frameName>imu_link</frameName>
      <topicName>imu</topicName>
      <serviceName>imu_service</serviceName>
      <gaussianNoise>0.0</gaussianNoise>
      <updateRate>200</updateRate>
      <imu>
        <noise>
          <type>gaussian</type>
          <rate>
            <mean>0.0</mean>
            <stddev>2e-4</stddev>
            <bias_mean>0.0000075</bias_mean>
            <bias_stddev>0.0000008</bias_stddev>
          </rate>
          <accel>
            <mean>0.0</mean>
            <stddev>1.7e-2</stddev>
            <bias_mean>0.1</bias_mean>
            <bias_stddev>0.001</bias_stddev>
          </accel>
        </noise>
      </imu>
    </plugin>
  </gazebo>
-->
  <!-- Camera & Laser -->
  <joint name="camera_joint" type="fixed">
    <axis xyz="0 1 0" />
    <origin xyz="0.05 0 0.25" rpy="0 0 0"/>
    <parent link="base_link"/>
    <child link="camera_link"/>
  </joint>

  <link name="camera_link">
    <collision>
      <origin xyz="0 0 0" rpy="0 0 0"/>
      <geometry>
        <box size="0.05 0.05 0.05"/>
      </geometry>
    </collision>

    <visual>
      <origin xyz="0 0 0" rpy="0 0 0"/>
      <geometry>
    <box size="0.05 0.05 0.05"/>
      </geometry>
    </visual>

    <inertial>
      <mass value="1e-5" />
      <origin xyz="0 0 0" rpy="0 0 0"/>
      <inertia ixx="1e-6" ixy="0" ixz="0" iyy="1e-6" iyz="0" izz="1e-6" />
    </inertial>
  </link>

<!-- hokuyo -->
  <gazebo reference="camera_link">
    <sensor type="ray" name="head_hokuyo_sensor">
      <pose>0 0 0 0 0 0</pose>
      <visualize>true</visualize>
      <update_rate>20</update_rate>
      <ray>
        <scan>
          <horizontal>
            <samples>240</samples>
            <resolution>0.5</resolution>
            <min_angle>-0.8</min_angle>
            <max_angle>0.8</max_angle>
          </horizontal>
        </scan>
        <range>
          <min>0.10</min>
          <max>20.0</max>
          <resolution>0.05</resolution>
        </range>
        <noise>
          <type>gaussian</type>
          <mean>0.0</mean>
          <stddev>0.01</stddev>
        </noise>
      </ray>
      <plugin name="gazebo_ros_head_hokuyo_controller" filename="libgazebo_ros_laser.so">
        <topicName>laser/scan</topicName>
        <frameName>camera_link</frameName>
      </plugin>
    </sensor>
  </gazebo>

  <gazebo reference="camera_link">
    <sensor type="camera" name="camera1">
      <update_rate>20.0</update_rate>
      <camera name="head">
        <horizontal_fov>1.3962634</horizontal_fov>
        <image>
          <width>800</width>
          <height>800</height>
          <format>R8G8B8</format>
        </image>
        <clip>
          <near>0.02</near>
          <far>300</far>
        </clip>
        <noise>
          <type>gaussian</type>
          <mean>0.0</mean>
          <stddev>0.00</stddev>
        </noise>
      </camera>
      <plugin name="camera_controller" filename="libgazebo_ros_camera.so">
        <alwaysOn>true</alwaysOn>
        <updateRate>0.0</updateRate>
        <cameraName>rover/camera1</cameraName>
        <imageTopicName>image_raw</imageTopicName>
        <cameraInfoTopicName>camera_info</cameraInfoTopicName>
        <frameName>camera_link</frameName>
        <hackBaseline>0.07</hackBaseline>
        <distortionK1>0.0</distortionK1>
        <distortionK2>0.0</distortionK2>
        <distortionK3>0.0</distortionK3>
        <distortionT1>0.0</distortionT1>
        <distortionT2>0.0</distortionT2>
      </plugin>
    </sensor>
  </gazebo>
<!--
  <gazebo>
    <plugin name="p3d_base_controller" filename="libgazebo_ros_p3d.so">
      <alwaysOn>true</alwaysOn>
      <updateRate>50.0</updateRate>
      <bodyName>base_link</bodyName>
      <topicName>odom</topicName>
      <gaussianNoise>0.01</gaussianNoise>
      <frameName>map</frameName>
      <xyzOffsets>0 0 0</xyzOffsets>
      <rpyOffsets>0 0 0</rpyOffsets>
    </plugin>
  </gazebo>
-->
  <gazebo>
        <plugin name="joint_state_publisher" filename="libgazebo_ros_joint_state_publisher.so">
           <jointName>joint_L_f, joint_L_m, joint_L_r, joint_R_f, joint_R_m, joint_R_r</jointName>
           <updateRate>10.0</updateRate>
           <alwaysOn>true</alwaysOn>
        </plugin>
    </gazebo>
<!--
  <gazebo reference="cam_link">
    <sensor type="depth" name="cam">
      <always_on>true</always_on>
      <update_rate>20.0</update_rate>
      <camera>
        <horizontal_fov>1.05</horizontal_fov>
        <image>
          <format>R8G8B8</format>
          <width>640</width>
          <height>480</height>
        </image>
        <clip>
          <near>0.05</near>
          <far>8.0</far>
        </clip>
      </camera>
      <plugin name="kinect_cam_controller" filename="libgazebo_ros_openni_kinect.so">
        <cameraName>cam</cameraName>
        <alwaysOn>true</alwaysOn>
        <updateRate>10</updateRate>
        <imageTopicName>rgb/image_raw</imageTopicName>
        <depthImageTopicName>depth/image_raw</depthImageTopicName>
        <pointCloudTopicName>depth/points</pointCloudTopicName>
        <cameraInfoTopicName>rgb/camera_info</cameraInfoTopicName>
        <depthImageCameraInfoTopicName>depth/camera_info</depthImageCameraInfoTopicName>
        <frameName>cam_frame_optical</frameName>
        <baseline>0.1</baseline>
        <distortion_k1>0.0</distortion_k1>
        <distortion_k2>0.0</distortion_k2>
        <distortion_k3>0.0</distortion_k3>
        <distortion_t1>0.0</distortion_t1>
        <distortion_t2>0.0</distortion_t2>
        <pointCloudCutoff>0.4</pointCloudCutoff>
      </plugin>
    </sensor>
  </gazebo> -->
</robot>