<?xml version="1.0" encoding="utf-8"?>
<!-- This URDF was automatically created by SolidWorks to URDF Exporter! Originally created by Stephen Brawner (brawner@gmail.com) 
     Commit Version: 1.6.0-1-g15f4949  Build Version: 1.6.7594.29634
     For more information, please see http://wiki.ros.org/sw_urdf_exporter -->
<robot
  name="SURover22_description_byerenna">
  <link
    name="base_link">
    <inertial>
      <origin
        xyz="0.00023486 -4.4786E-05 -0.14162"
        rpy="0 0 0" />
      <mass
        value="20.605" />
      <inertia
        ixx="0.454"
        ixy="1.9549E-09"
        ixz="0.00084823"
        iyy="1.0629"
        iyz="1.6096E-08"
        izz="1.4823" />
    </inertial>
    <visual>
      <origin
        xyz="0 0 0"
        rpy="0 0 0" />
      <geometry>
        <mesh
          filename="package://SURover22_description_byerenna/meshes/base_link.STL" />
      </geometry>
      <material
        name="">
        <color
          rgba="0.7451 0.7451 0.7451 1" />
      </material>
    </visual>
    <collision>
      <origin
        xyz="0 0 0"
        rpy="0 0 0" />
      <geometry>
        <mesh
          filename="package://SURover22_description_byerenna/meshes/base_link.STL" />
      </geometry>
    </collision>
  </link>
  <link
    name="R-front">
    <inertial>
      <origin
        xyz="8.8818E-16 -0.0375 1.6653E-16"
        rpy="0 0 0" />
      <mass
        value="2.3326" />
      <inertia
        ixx="0.0069833"
        ixy="-1.1181E-16"
        ixz="7.4623E-19"
        iyy="0.01178"
        iyz="-2.014E-17"
        izz="0.0069833" />
    </inertial>
    <visual>
      <origin
        xyz="0 0 0"
        rpy="0 0 0" />
      <geometry>
        <mesh
          filename="package://SURover22_description_byerenna/meshes/R-front.STL" />
      </geometry>
      <material
        name="">
        <color
          rgba="0.79216 0.81961 0.93333 1" />
      </material>
    </visual>
    <collision>
      <origin
        xyz="0 0 0"
        rpy="0 0 0" />
      <geometry>
        <mesh
          filename="package://SURover22_description_byerenna/meshes/R-front.STL" />
      </geometry>
    </collision>
  </link>
  <joint
    name="joint-R-f"
    type="continuous">
    <origin
      xyz="0.548838296645782 -0.351080000000064 -0.428087514508932"
      rpy="0 0 0" />
    <parent
      link="base_link" />
    <child
      link="R-front" />
    <axis
      xyz="0 -1 0" />
  </joint>
  <link
    name="R-mid">
    <inertial>
      <origin
        xyz="-5.55111512312578E-17 -0.0375000000000623 -5.55111512312578E-17"
        rpy="0 0 0" />
      <mass
        value="2.33263254529042" />
      <inertia
        ixx="0.0069833186824632"
        ixy="-1.30245751233354E-19"
        ixz="-7.41033887658693E-19"
        iyy="0.0117797943537166"
        iyz="1.28115366404075E-19"
        izz="0.0069833186824632" />
    </inertial>
    <visual>
      <origin
        xyz="0 0 0"
        rpy="0 0 0" />
      <geometry>
        <mesh
          filename="package://SURover22_description_byerenna/meshes/R-mid.STL" />
      </geometry>
      <material
        name="">
        <color
          rgba="0.792156862745098 0.819607843137255 0.933333333333333 1" />
      </material>
    </visual>
    <collision>
      <origin
        xyz="0 0 0"
        rpy="0 0 0" />
      <geometry>
        <mesh
          filename="package://SURover22_description_byerenna/meshes/R-mid.STL" />
      </geometry>
    </collision>
  </link>
  <joint
    name="joint-R-m"
    type="continuous">
    <origin
      xyz="0.068456 -0.38608 -0.42809"
      rpy="0 0 0" />
    <parent
      link="base_link" />
    <child
      link="R-mid" />
    <axis
      xyz="0 -1 0" />
  </joint>
  <link
    name="R-rear">
    <inertial>
      <origin
        xyz="6.3838E-15 -0.0375 -5.107E-15"
        rpy="0 0 0" />
      <mass
        value="2.3326" />
      <inertia
        ixx="0.0069833"
        ixy="-8.3231E-16"
        ixz="8.0388E-19"
        iyy="0.01178"
        iyz="6.734E-16"
        izz="0.0069833" />
    </inertial>
    <visual>
      <origin
        xyz="0 0 0"
        rpy="0 0 0" />
      <geometry>
        <mesh
          filename="package://SURover22_description_byerenna/meshes/R-rear.STL" />
      </geometry>
      <material
        name="">
        <color
          rgba="0.79216 0.81961 0.93333 1" />
      </material>
    </visual>
    <collision>
      <origin
        xyz="0 0 0"
        rpy="0 0 0" />
      <geometry>
        <mesh
          filename="package://SURover22_description_byerenna/meshes/R-rear.STL" />
      </geometry>
    </collision>
  </link>
  <joint
    name="joint-R-r"
    type="continuous">
    <origin
      xyz="-0.43561 -0.38608 -0.42822"
      rpy="0 0 0" />
    <parent
      link="base_link" />
    <child
      link="R-rear" />
    <axis
      xyz="0 -1 0" />
  </joint>
  <link
    name="L-front">
    <inertial>
      <origin
        xyz="9.992E-16 -0.0375 0"
        rpy="0 0 0" />
      <mass
        value="2.3326" />
      <inertia
        ixx="0.0069833"
        ixy="-1.245E-16"
        ixz="-6.9538E-33"
        iyy="0.01178"
        iyz="2.6789E-19"
        izz="0.0069833" />
    </inertial>
    <visual>
      <origin
        xyz="0 0 0"
        rpy="0 0 0" />
      <geometry>
        <mesh
          filename="package://SURover22_description_byerenna/meshes/L-front.STL" />
      </geometry>
      <material
        name="">
        <color
          rgba="0.79216 0.81961 0.93333 1" />
      </material>
    </visual>
    <collision>
      <origin
        xyz="0 0 0"
        rpy="0 0 0" />
      <geometry>
        <mesh
          filename="package://SURover22_description_byerenna/meshes/L-front.STL" />
      </geometry>
    </collision>
  </link>
  <joint
    name="joint-L-f"
    type="continuous">
    <origin
      xyz="0.548812606572592 0.426079999999846 -0.428126101607028"
      rpy="0 0 0" />
    <parent
      link="base_link" />
    <child
      link="L-front" />
    <axis
      xyz="0 -1 0" />
  </joint>
  <link
    name="L-mid">
    <inertial>
      <origin
        xyz="4.774E-15 -0.0375 -3.3307E-16"
        rpy="0 0 0" />
      <mass
        value="2.3326" />
      <inertia
        ixx="0.0069833"
        ixy="-6.1418E-16"
        ixz="-2.7012E-19"
        iyy="0.01178"
        iyz="5.0407E-17"
        izz="0.0069833" />
    </inertial>
    <visual>
      <origin
        xyz="0 0 0"
        rpy="0 0 0" />
      <geometry>
        <mesh
          filename="package://SURover22_description_byerenna/meshes/L-mid.STL" />
      </geometry>
      <material
        name="">
        <color
          rgba="0.79216 0.81961 0.93333 1" />
      </material>
    </visual>
    <collision>
      <origin
        xyz="0 0 0"
        rpy="0 0 0" />
      <geometry>
        <mesh
          filename="package://SURover22_description_byerenna/meshes/L-mid.STL" />
      </geometry>
    </collision>
  </link>
  <joint
    name="joint-L-m"
    type="continuous">
    <origin
      xyz="0.068429 0.46108 -0.42809"
      rpy="0 0 0" />
    <parent
      link="base_link" />
    <child
      link="L-mid" />
    <axis
      xyz="0 -1 0" />
  </joint>
  <link
    name="L-rear">
    <inertial>
      <origin
        xyz="4.774E-15 -0.0375 -5.9952E-15"
        rpy="0 0 0" />
      <mass
        value="2.3326" />
      <inertia
        ixx="0.0069833"
        ixy="-6.2773E-16"
        ixz="-2.1099E-19"
        iyy="0.01178"
        iyz="7.7451E-16"
        izz="0.0069833" />
    </inertial>
    <visual>
      <origin
        xyz="0 0 0"
        rpy="0 0 0" />
      <geometry>
        <mesh
          filename="package://SURover22_description_byerenna/meshes/L-rear.STL" />
      </geometry>
      <material
        name="">
        <color
          rgba="0.79216 0.81961 0.93333 1" />
      </material>
    </visual>
    <collision>
      <origin
        xyz="0 0 0"
        rpy="0 0 0" />
      <geometry>
        <mesh
          filename="package://SURover22_description_byerenna/meshes/L-rear.STL" />
      </geometry>
    </collision>
  </link>
  <joint
    name="joint-L-r"
    type="continuous">
    <origin
      xyz="-0.43564 0.46108 -0.42817"
      rpy="0 0 0" />
    <parent
      link="base_link" />
    <child
      link="L-rear" />
    <axis
      xyz="0 -1 0" />
  </joint>

  <gazebo>
    <plugin name="differential_drive_controller" filename="libgazebo_ros_diff_drive.so">
      <legacyMode>false</legacyMode>
      <alwaysOn>true</alwaysOn>
      <updateRate>10</updateRate>
      <leftJoint>joint-L-r</leftJoint>
      <leftJoint>joint-R-r</leftJoint>
      <leftJoint>joint-R-m</leftJoint>
      <rightJoint>joint-L-m</rightJoint>
      <rightJoint>joint-R-f</rightJoint>
      <rightJoint>joint-L-f</rightJoint>
      <wheelSeparation>0.30</wheelSeparation>
      <wheelDiameter>0.2</wheelDiameter>
      <torque>30</torque>
      <commandTopic>cmd_vel</commandTopic>
      <odometryTopic>odom</odometryTopic>
      <odometryFrame>odom</odometryFrame>
      <robotBaseFrame>chassis</robotBaseFrame>
    </plugin>
  </gazebo>
</robot>